

  tryCatch
    ✓ takes two functions and return a function
    1) returns a function with the same arity as the `tryer` function
    ✓ returns the value of the first function if it does not throw
    ✓ returns the value of the second function if the first function throws
    ✓ the second function gets passed the error object and the same arguments as the first function


  4 passing (58ms)
  1 failing

  1) tryCatch
       returns a function with the same arity as the `tryer` function:

      AssertionError [ERR_ASSERTION]: Expected values to be strictly equal:

'0' !== '1'

      + expected - actual

      -0
      +1
      
      at strictEqual (test/shared/eq.js:8:10)
      at Context.eq (test/tryCatch.js:26:5)
      at processImmediate (internal/timers.js:456:21)



